Workbook

Sheet OKZ667
C1: PERSONERÍA DE BOGOTÁ, D. C. | F1: FORMATO HOJA DE VIDA DE VEHÍCULOS | T1: Codigo: 09-FR-40
T2: Versión: 03 | V2: Pagina: 1
T3: Vigente desde: 24/10/2019
C5: HOJA DE VIDA DEL VEHICULO
C6: INFORMACION GENERAL DEL VEHICULO
C7: PLACA | D7: LÍNEA | E7: TIPO | F7: MARCA | H7: COLOR | J7: NÚMERO DE MOTOR | L7: NÚMERO DE CHASIS | M7: CILINDRAJE | N7: SERIE No. | P7: TIPO CARROCERÍA | R7: LICENCIA TRÁNSITO No. | T7: No, DE PASAJEROS | U7: TIPO COMBUSTIBLE:
C8: OKZ667 | D8: DUTER DINAMIQUE | E8: CAMIONETA | F8: RENAULT | H8: BLANCO ARTICA | J8: E412C011375 | L8: 9FBHSR5B6HM294196 | M8: 1998 | N8: 9FBHSR5B6HM294197 | P8: CAMIONETA | R8: 10012891689 | T8: 5 | U8: GASOLINA
C9: POLIZA SOAT | I9: CERTIFICADO REVISIÓN TECNICO-MECÁNICA Y DE GASES | P9: INCIDENTES O ACCIDENTES DE TRÁNSITO
C10: Número de poliza | D10: Inicio de vigencia | E10: Fin de vigencia | F10: Número de poliza | G10: Inicio de vigencia | H10: Fin de vigencia | I10: Centro Diagnóstico Autorizado | K10: Inicio de vigencia | L10: Fin de vigencia | N10: Inicio de vigencia | O10: Fin de vigencia | P10: Fecha del evento | Q10: Nombre del Conductor que reporta | T10: Tipo de evento: Incidente ó Accidente
C11: 165054492 | D11: 42683 | E11: 43047
C12: 7.0080015e+15 | D12: 43048 | E12: 43412
C13: 111608906 | D13: 43412 | E13: 43776
C14: 14730800002080 | D14: 44143 | E14: 44507
C15: 9201121000598 | D15: 44508 | E15: 44872
C17: DETALLE DE MANTENIMIENTO PREVENTIVO Y CORRECTIVO
C18: Fecha Novedad de Falla Inspección Diaria Vehicular - I.D.V. ó Revisión Preventiva | D18: Kilometraje (en la fecha de la novedad) | E18: Tipo de novedad reportada en I.D.V. ó Revisión Preventiva | F18: Contrato No. | G18: Proveedor | H18: Kilometraje de la autorización de servicios | I18: Fecha factura | J18: Factura No. | K18: Tipo de mantenimiento | L18: Repuestos y Mano de obra | M18: Cant | N18: Valor Unitario Repuesto | O18: Subtotal Repuestos =(P*Q) | P18: IVA =(R*S) | Q18: Valor total repuesto =(R+S) | R18: Valor Unitario Mano de Obra | S18: Subtotal Mano de obra =(P*U) | T18: IVA (V*W) | U18: Valor total Mano de Obra =(V+W) | V18: Total Facturado =(T+X) | W18: TOTAL FACTURA | X18: DOCUMENTOS SOPORTE
C19: 42900 | H19: 9168 | I19: 42996 | J19: FS7161 | K19: PREVENTIVO | L19: LAVADO GENERAL | M19: 1 | N19: 0 | O19: =+N19*M19 -> 0 | P19: =+O19*0.19 -> 0 | Q19: =+P19+O19 -> 0 | R19: 25210 | S19: =+R19*M19 -> 25210 | T19: =+S19*0.19 -> 4789.9 | U19: =+T19+S19 -> 29999.9 | V19: =+U19+Q19 -> 29999.9
C20: 42996 | H20: 12443 | I20: 43025 | J20: FS7263 | K20: PREVENTIVO | L20: PLUMILLA LIMPIABRISA DELANTERA | M20: 2 | N20: 0 | O20: =+N20*M20 -> 0 | P20: =+O20*0.19 -> 0 | Q20: =+P20+O20 -> 0 | R20: 29700 | S20: =+R20*M20 -> 59400 | T20: =+S20*0.19 -> 11286 | U20: =+T20+S20 -> 70686 | V20: =+U20+Q20 -> 70686
C21: 42996 | H21: 12443 | I21: 43025 | J21: FS7263 | K21: PREVENTIVO | L21: PLUMILLA LIMPIABRISA TRASERA | M21: 1 | N21: 0 | O21: =+N21*M21 -> 0 | P21: =+O21*0.19 -> 0 | Q21: =+P21+O21 -> 0 | R21: 27500 | S21: =+R21*M21 -> 27500 | T21: =+S21*0.19 -> 5225 | U21: =+T21+S21 -> 32725 | V21: =+U21+Q21 -> 32725
H22: 12443 | I22: 43054 | J22: 7406 | K22: PREVENTIVO | L22: LAVADO GENERAL | M22: 1 | N22: 0 | O22: =+N22*M22 -> 0 | P22: =+O22*0.19 -> 0 | Q22: =+P22+O22 -> 0 | R22: 25210 | S22: =+R22*M22 -> 25210 | T22: =+S22*0.19 -> 4789.9 | U22: =+T22+S22 -> 29999.9 | V22: =+U22+Q22 -> 29999.9
H23: 13371 | I23: 43054 | J23: 7419 | K23: PREVENTIVO | L23: LAVADO GENERAL | M23: 1 | N23: 0 | O23: =+N23*M23 -> 0 | P23: =+O23*0.19 -> 0 | Q23: =+P23+O23 -> 0 | R23: 25210 | S23: =+R23*M23 -> 25210 | T23: =+S23*0.19 -> 4789.9 | U23: =+T23+S23 -> 29999.9 | V23: =+U23+Q23 -> 29999.9
H24: 15362 | I24: 43082 | J24: 7473 | K24: PREVENTIVO | L24: LAVADO GENERAL | M24: 1 | N24: 0 | O24: =+N24*M24 -> 0 | P24: =+O24*0.19 -> 0 | Q24: =+P24+O24 -> 0 | R24: 25210 | S24: =+R24*M24 -> 25210 | T24: =+S24*0.19 -> 4789.9 | U24: =+T24+S24 -> 29999.9 | V24: =+U24+Q24 -> 29999.9
H25: 15362 | I25: 43082 | J25: 7473 | K25: PREVENTIVO | L25: LAVADO EXTERIOR | M25: 1 | N25: 0 | O25: =+N25*M25 -> 0 | P25: =+O25*0.19 -> 0 | Q25: =+P25+O25 -> 0 | R25: 10084 | S25: =+R25*M25 -> 10084 | T25: =+S25*0.19 -> 1915.96 | U25: =+T25+S25 -> 11999.96 | V25: =+U25+Q25 -> 11999.96
H26: 15690 | I26: 43082 | J26: 7466 | K26: PREVENTIVO | L26: LAVADO EXTERIOR | M26: 1 | N26: 0 | O26: =+N26*M26 -> 0 | P26: =+O26*0.19 -> 0 | Q26: =+P26+O26 -> 0 | R26: 10084 | S26: =+R26*M26 -> 10084 | T26: =+S26*0.19 -> 1915.96 | U26: =+T26+S26 -> 11999.96 | V26: =+U26+Q26 -> 11999.96
H27: 14671 | I27: 43089 | J27: 7586 | K27: PREVENTIVO | L27: LAVADO GENERAL | M27: 1 | N27: 0 | O27: =+N27*M27 -> 0 | P27: =+O27*0.19 -> 0 | Q27: =+P27+O27 -> 0 | R27: 25210 | S27: =+R27*M27 -> 25210 | T27: =+S27*0.19 -> 4789.9 | U27: =+T27+S27 -> 29999.9 | V27: =+U27+Q27 -> 29999.9
H28: 15690 | I28: 43082 | J28: 7466 | K28: PREVENTIVO | L28: LAVADO EXTERIOR | M28: 1 | N28: 0 | O28: =+N28*M28 -> 0 | P28: =+O28*0.19 -> 0 | Q28: =+P28+O28 -> 0 | R28: 10084 | S28: =+R28*M28 -> 10084 | T28: =+S28*0.19 -> 1915.96 | U28: =+T28+S28 -> 11999.96 | V28: =+U28+Q28 -> 11999.96
H29: 15362 | I29: 13/12/018 | J29: 7473 | K29: PREVENTIVO | L29: LAVADO GENERAL | M29: 1 | N29: 0 | O29: =+N29*M29 -> 0 | P29: =+O29*0.19 -> 0 | Q29: =+P29+O29 -> 0 | R29: 25210 | S29: =+R29*M29 -> 25210 | T29: =+S29*0.19 -> 4789.9 | U29: =+T29+S29 -> 29999.9 | V29: =+U29+Q29 -> 29999.9
H30: 14671 | I30: 13/12/018 | J30: 7477 | K30: PREVENTIVO | L30: LAVADO EXTERIOR | M30: 1 | N30: 0 | O30: =+N30*M30 -> 0 | P30: =+O30*0.19 -> 0 | Q30: =+P30+O30 -> 0 | R30: 10084 | S30: =+R30*M30 -> 10084 | T30: =+S30*0.19 -> 1915.96 | U30: =+T30+S30 -> 11999.96 | V30: =+U30+Q30 -> 11999.96
H31: 17919 | I31: 43150 | J31: 7624 | K31: PREVENTIVO | L31: LAVADO EXTERIOR | M31: 1 | N31: 0 | O31: =+N31*M31 -> 0 | P31: =+O31*0.19 -> 0 | Q31: =+P31+O31 -> 0 | R31: 10084 | S31: =+R31*M31 -> 10084 | T31: =+S31*0.19 -> 1915.96 | U31: =+T31+S31 -> 11999.96 | V31: =+U31+Q31 -> 11999.96
H32: 22243 | I32: 43220 | J32: 7736 | K32: PREVENTIVO | L32: LAVADO GENERAL | M32: 1 | N32: 0 | O32: =+N32*M32 -> 0 | P32: =+O32*0.19 -> 0 | Q32: =+P32+O32 -> 0 | R32: 25210 | S32: =+R32*M32 -> 25210 | T32: =+S32*0.19 -> 4789.9 | U32: =+T32+S32 -> 29999.9 | V32: =+U32+Q32 -> 29999.9
H33: 22243 | I33: 43266 | J33: 7774 | K33: PREVENTIVO | L33: LAVADO GENERAL | M33: 1 | N33: 0 | O33: =+N33*M33 -> 0 | P33: =+O33*0.19 -> 0 | Q33: =+P33+O33 -> 0 | R33: 25210 | S33: =+R33*M33 -> 25210 | T33: =+S33*0.19 -> 4789.9 | U33: =+T33+S33 -> 29999.9 | V33: =+U33+Q33 -> 29999.9
I34: 43426 | J34: FT 119936 | K34: PREVENTIVO | L34: LAVADO GENERAL | M34: 1 | N34: 0 | O34: =+N34*M34 -> 0 | P34: =+O34*0.19 -> 0 | Q34: =+P34+O34 -> 0 | R34: 30252 | S34: =+R34*M34 -> 30252 | T34: =+S34*0.19 -> 5747.88 | U34: =+T34+S34 -> 35999.88 | V34: =+U34+Q34 -> 35999.88
I35: 43610 | J35: FT 120783 | K35: PREVENTIVO | L35: FILTRO ACEITE | M35: 1 | N35: 25412 | O35: =+N35*M35 -> 25412 | P35: =+O35*0.19 -> 4828.28 | Q35: =+P35+O35 -> 30240.28 | R35: 0 | S35: =+R35*M35 -> 0 | T35: =+S35*0.19 -> 0 | U35: =+T35+S35 -> 0 | V35: =+U35+Q35 -> 30240.28
I36: 43610 | J36: FT 120783 | K36: PREVENTIVO | L36: FILTRO AIRE ACONDICIONADO | M36: 1 | N36: 34622 | O36: =+N36*M36 -> 34622 | P36: =+O36*0.19 -> 6578.18 | Q36: =+P36+O36 -> 41200.18 | R36: 0 | S36: =+R36*M36 -> 0 | T36: =+S36*0.19 -> 0 | U36: =+T36+S36 -> 0 | V36: =+U36+Q36 -> 41200.18
I37: 43610 | J37: FT 120783 | K37: PREVENTIVO | L37: FILTRO AIRE | M37: 1 | N37: 36303 | O37: =+N37*M37 -> 36303 | P37: =+O37*0.19 -> 6897.57 | Q37: =+P37+O37 -> 43200.57 | R37: 0 | S37: =+R37*M37 -> 0 | T37: =+S37*0.19 -> 0 | U37: =+T37+S37 -> 0 | V37: =+U37+Q37 -> 43200.57
I38: 43610 | J38: FT 120783 | K38: PREVENTIVO | L38: ACEITE MOTOR | M38: 6 | N38: 34560 | O38: =+N38*M38 -> 207360 | P38: =+O38*0.19 -> 39398.4 | Q38: =+P38+O38 -> 246758.4 | R38: 0 | S38: =+R38*M38 -> 0 | T38: =+S38*0.19 -> 0 | U38: =+T38+S38 -> 0 | V38: =+U38+Q38 -> 246758.4
I39: 43610 | J39: FT 120783 | K39: PREVENTIVO | L39: LIQUIDO REFRIGERANTE | M39: 4 | N39: 9454 | O39: =+N39*M39 -> 37816 | P39: =+O39*0.19 -> 7185.04 | Q39: =+P39+O39 -> 45001.04 | R39: 0 | S39: =+R39*M39 -> 0 | T39: =+S39*0.19 -> 0 | U39: =+T39+S39 -> 0 | V39: =+U39+Q39 -> 45001.04
I40: 43610 | J40: FT 120783 | K40: CORRECTIVO | L40: JUEGO DE SALPICADERAS | M40: 1 | N40: 100800 | O40: =+N40*M40 -> 100800 | P40: =+O40*0.19 -> 19152 | Q40: =+P40+O40 -> 119952 | R40: 0 | S40: =+R40*M40 -> 0 | T40: =+S40*0.19 -> 0 | U40: =+T40+S40 -> 0 | V40: =+U40+Q40 -> 119952
I41: 43610 | J41: FT 120783 | K41: CORRECTIVO | L41: TAPETES UNIVERSAL | M41: 1 | N41: 150000 | O41: =+N41*M41 -> 150000 | P41: =+O41*0.19 -> 28500 | Q41: =+P41+O41 -> 178500 | R41: 0 | S41: =+R41*M41 -> 0 | T41: =+S41*0.19 -> 0 | U41: =+T41+S41 -> 0 | V41: =+U41+Q41 -> 178500
I42: 43610 | J42: FT 120783 | K42: CORRECTIVO | L42: REMACHE POP | M42: 30 | N42: 400 | O42: =+N42*M42 -> 12000 | P42: =+O42*0.19 -> 2280 | Q42: =+P42+O42 -> 14280 | R42: 0 | S42: =+R42*M42 -> 0 | T42: =+S42*0.19 -> 0 | U42: =+T42+S42 -> 0 | V42: =+U42+Q42 -> 14280
...

Sheet Hoja1
A1: OKZ667 | B1: Repuestos y Mano de obra | C1: Tipo de mantenimiento
A2: TALLERES EL NORTE | B2: ABRAZADERA 450x720 NEGRA | C2: CORRECTIVO
A3: INVERSIONES EL NORTE SAS | B3: ACEITE CHEVRON PARA HIDRAULICO | C3: PREVENTIVO
A4: TALLERES EL NORTE | B4: ACEITE HID ACD PLUS ATF TYPE VI | C4: PREVENTIVO
A5: INVERSIONES EL NORTE SAS | B5: ACEITE HIDRAULICO | C5: PREVENTIVO
A6: INVERSIONES EL NORTE SAS | B6: ACEITE HIDRAULICO CAJA | C6: PREVENTIVO
A7: TALLERES EL NORTE | B7: ACEITE HIDRAULICO DIRECCION | C7: PREVENTIVO
A8: TALLERES EL NORTE | B8: ACEITE MOTOR | C8: PREVENTIVO
A9: TALLERES EL NORTE | B9: ACEITE MOTOR AC DELCO SELE 20W50 | C9: PREVENTIVO
A10: TALLERES EL NORTE | B10: ACEITE SINTETICO | C10: PREVENTIVO
A11: TALLERES EL NORTE | B11: ACEITE SINTETICO 10W40 | C11: PREVENTIVO
A12: INVERSIONES EL NORTE SAS | B12: ACEITE SINTETICO MOTOR | C12: PREVENTIVO
... A417: INVERSIONES EL NORTE SAS | B417: CAMBIO DE FILTROS | C417: PREVENTIVO
