Workbook

Sheet OKZ666
F1: FORMATO HOJA DE VIDA DE VEHÍCULOS | T1: Codigo: 09-FR-40
C2: PERSONERÍA DE BOGOTÁ, D. C. | T2: Versión: 03 | V2: Pagina: 1
T3: Vigente desde: 24/10/2019
C6: INFORMACION GENERAL DEL VEHICULO
C7: PLACA | D7: LÍNEA | E7: TIPO | F7: MARCA | H7: COLOR | J7: NÚMERO DE MOTOR | L7: NÚMERO DE CHASIS | M7: CILINDRAJE | N7: SERIE No. | P7: TIPO CARROCERÍA | R7: LICENCIA TRÁNSITO No. | T7: No, DE PASAJEROS | U7: TIPO COMBUSTIBLE:
C8: OKZ666 | D8: DUSTER DYNAMIQUE | E8: WAGON | F8: RENAULT | H8: BLANCO | J8: E412C011375 | L8: 9FBHSR5B6HM294196 | M8: 1998 | N8: 9FBHSR5B6HM294196 | P8: WAGON | R8: 10012891275 | T8: 5 | U8: GASOLINA
I9: CERTIFICADO REVISIÓN TECNICO-MECÁNICA Y DE GASES | P9: INCIDENTES O ACCIDENTES DE TRÁNSITO
C10: Número de poliza | D10: Inicio de vigencia | E10: Fin de vigencia | F10: Número de poliza | G10: Inicio de vigencia | H10: Fin de vigencia | I10: Centro Diagnóstico Autorizado | K10: Inicio de vigencia | L10: Fin de vigencia | N10: Inicio de vigencia | O10: Fin de vigencia | P10: Fecha del evento | Q10: Nombre del Conductor que reporta | T10: Tipo de evento: Incidente ó Accidente
C11: 165054481 | D11: 42683 | E11: 43047
C12: 7.0080015e+15 | D12: 43048 | E12: 43412
C13: 111608895 | D13: 43412 | E13: 43776
C14: 8022168900 | D14: 43777 | E14: 44142
C15: 14730800002070 | D15: 44143 | E15: 44507
C16: 921121000597 | D16: 44508 | E16: 44872
C17: DETALLE DE MANTENIMIENTO PREVENTIVO Y CORRECTIVO
C18: Fecha Novedad de Falla Inspección Diaria Vehicular - I.D.V. ó Revisión Preventiva | D18: Kilometraje (en la fecha de la novedad) | E18: Tipo de novedad reportada en I.D.V. ó Revisión Preventiva | F18: Contrato No. | G18: Proveedor | H18: Kilometraje de la autorización de servicios | I18: Fecha factura | J18: Factura No. | K18: Tipo de mantenimiento | L18: Repuestos y Mano de obra | M18: Cant | N18: Valor Unitario Repuesto | O18: Subtotal Repuestos =(P*Q) | P18: IVA =(R*S) | Q18: Valor total repuesto =(R+S) | R18: Valor Unitario Mano de Obra | S18: Subtotal Mano de obra =(P*U) | T18: IVA (V*W) | U18: Valor total Mano de Obra =(V+W) | V18: Total Facturado =(T+X) | W18: TOTAL FACTURA | X18: DOCUMENTOS SOPORTE
C19: 42976 | H19: 11822 | I19: 42976 | J19: FS7048 | K19: PREVENTIVO | L19: LAVADO GENERAL | M19: 1 | N19: 0 | O19: =+N19*M19 -> 0 | P19: =+O19*0.19 -> 0 | Q19: =+P19+O19 -> 0 | R19: 25210 | S19: =+R19*M19 -> 25210 | T19: =+S19*0.19 -> 4789.9 | U19: =+T19+S19 -> 29999.9 | V19: =+U19+Q19 -> 29999.9
C20: 42948 | H20: 13853 | I20: 42996 | J20: 7166 | K20: PREVENTIVO | L20: LAVADO GENERAL | M20: 1 | N20: 0 | O20: =+N20*M20 -> 0 | P20: =+O20*0.19 -> 0 | Q20: =+P20+O20 -> 0 | R20: 25210 | S20: =+R20*M20 -> 25210 | T20: =+S20*0.19 -> 4789.9 | U20: =+T20+S20 -> 29999.9 | V20: =+U20+Q20 -> 29999.9
N21: 0 | O21: =+N21*M21 -> 0 | P21: =+O21*0.19 -> 0 | Q21: =+P21+O21 -> 0 | R21: 0 | S21: =+R21*M21 -> 0 | T21: =+S21*0.19 -> 0 | U21: =+T21+S21 -> 0 | V21: =+U21+Q21 -> 0
N22: 0 | O22: =+N22*M22 -> 0 | P22: =+O22*0.19 -> 0 | Q22: =+P22+O22 -> 0 | R22: 0 | S22: =+R22*M22 -> 0 | T22: =+S22*0.19 -> 0 | U22: =+T22+S22 -> 0 | V22: =+U22+Q22 -> 0
C23: 42934 | H23: 15477 | I23: 42996 | J23: 7188 | K23: PREVENTIVO | L23: LAVADO EXTERIOR | M23: 1 | N23: 0 | O23: =+N23*M23 -> 0 | P23: =+O23*0.19 -> 0 | Q23: =+P23+O23 -> 0 | R23: 10084 | S23: =+R23*M23 -> 10084 | T23: =+S23*0.19 -> 1915.96 | U23: =+T23+S23 -> 11999.96 | V23: =+U23+Q23 -> 11999.96
N24: 0 | O24: =+N24*M24 -> 0 | P24: =+O24*0.19 -> 0 | Q24: =+P24+O24 -> 0 | R24: 0 | S24: =+R24*M24 -> 0 | T24: =+S24*0.19 -> 0 | U24: =+T24+S24 -> 0 | V24: =+U24+Q24 -> 0
C25: 42951 | H25: 16563 | I25: 42996 | J25: 7203 | K25: PREVENTIVO | L25: LAVADO EXTERIOR | M25: 1 | N25: 0 | O25: =+N25*M25 -> 0 | P25: =+O25*0.19 -> 0 | Q25: =+P25+O25 -> 0 | R25: 10084 | S25: =+R25*M25 -> 10084 | T25: =+S25*0.19 -> 1915.96 | U25: =+T25+S25 -> 11999.96 | V25: =+U25+Q25 -> 11999.96
N26: 0 | O26: =+N26*M26 -> 0 | P26: =+O26*0.19 -> 0 | Q26: =+P26+O26 -> 0 | R26: 0 | S26: =+R26*M26 -> 0 | T26: =+S26*0.19 -> 0 | U26: =+T26+S26 -> 0 | V26: =+U26+Q26 -> 0
H27: 18665 | I27: 43025 | J27: FS 7262 | K27: PREVENTIVO | L27: PLUMILLA LIMPIABRISAS DELANTERA | M27: 2 | N27: 29700 | O27: =+N27*M27 -> 59400 | P27: =+O27*0.19 -> 11286 | Q27: =+P27+O27 -> 70686 | R27: 0 | S27: =+R27*M27 -> 0 | T27: =+S27*0.19 -> 0 | U27: =+T27+S27 -> 0 | V27: =+U27+Q27 -> 70686
H28: 18665 | I28: 43025 | J28: FS 7262 | K28: PREVENTIVO | L28: PLUMILLA LIMPIABRISAS TRASERA | M28: 1 | N28: 27500 | O28: =+N28*M28 -> 27500 | P28: =+O28*0.19 -> 5225 | Q28: =+P28+O28 -> 32725 | R28: 0 | S28: =+R28*M28 -> 0 | T28: =+S28*0.19 -> 0 | U28: =+T28+S28 -> 0 | V28: =+U28+Q28 -> 32725
N29: 0 | O29: =+N29*M29 -> 0 | P29: =+O29*0.19 -> 0 | Q29: =+P29+O29 -> 0 | R29: 0 | S29: =+R29*M29 -> 0 | T29: =+S29*0.19 -> 0 | U29: =+T29+S29 -> 0 | V29: =+U29+Q29 -> 0
H30: 19855 | I30: 43054 | J30: 7415 | K30: PREVENTIVO | L30: LAVADO GENERAL | M30: 1 | N30: 0 | O30: =+N30*M30 -> 0 | P30: =+O30*0.19 -> 0 | Q30: =+P30+O30 -> 0 | R30: 25210 | S30: =+R30*M30 -> 25210 | T30: =+S30*0.19 -> 4789.9 | U30: =+T30+S30 -> 29999.9 | V30: =+U30+Q30 -> 29999.9
H31: 21475 | I31: 43054 | J31: 7432 | K31: PREVENTIVO | L31: LAVADO GENERAL | M31: 1 | N31: 0 | O31: =+N31*M31 -> 0 | P31: =+O31*0.19 -> 0 | Q31: =+P31+O31 -> 0 | R31: 25210 | S31: =+R31*M31 -> 25210 | T31: =+S31*0.19 -> 4789.9 | U31: =+T31+S31 -> 29999.9 | V31: =+U31+Q31 -> 29999.9
H32: 18665 | I32: 43054 | J32: 7405 | K32: PREVENTIVO | L32: LAVADO EXTERIOR | M32: 1 | N32: 0 | O32: =+N32*M32 -> 0 | P32: =+O32*0.19 -> 0 | Q32: =+P32+O32 -> 0 | R32: 10084 | S32: =+R32*M32 -> 10084 | T32: =+S32*0.19 -> 1915.96 | U32: =+T32+S32 -> 11999.96 | V32: =+U32+Q32 -> 11999.96
H33: 19045 | I33: 43054 | J33: 7399 | K33: PREVENTIVO | L33: LAVADO EXTERIOR | M33: 1 | N33: 0 | O33: =+N33*M33 -> 0 | P33: =+O33*0.19 -> 0 | Q33: =+P33+O33 -> 0 | R33: 10084 | S33: =+R33*M33 -> 10084 | T33: =+S33*0.19 -> 1915.96 | U33: =+T33+S33 -> 11999.96 | V33: =+U33+Q33 -> 11999.96
H34: 19045 | I34: 43054 | J34: 7399 | K34: PREVENTIVO | L34: DESPINCHE DE LLANTA | M34: 1 | N34: 0 | O34: =+N34*M34 -> 0 | P34: =+O34*0.19 -> 0 | Q34: =+P34+O34 -> 0 | R34: 12605 | S34: =+R34*M34 -> 12605 | T34: =+S34*0.19 -> 2394.95 | U34: =+T34+S34 -> 14999.95 | V34: =+U34+Q34 -> 14999.95
H35: 23112 | I35: 43082 | J35: 7470 | K35: PREVENTIVO | L35: LAVADO GENERAL | M35: 1 | N35: 0 | O35: =+N35*M35 -> 0 | P35: =+O35*0.19 -> 0 | Q35: =+P35+O35 -> 0 | R35: 25210 | S35: =+R35*M35 -> 25210 | T35: =+S35*0.19 -> 4789.9 | U35: =+T35+S35 -> 29999.9 | V35: =+U35+Q35 -> 29999.9
H36: 24000 | I36: 43070 | J36: 7463 | K36: PREVENTIVO | L36: LAVADO GENERAL | M36: 1 | N36: 0 | O36: =+N36*M36 -> 0 | P36: =+O36*0.19 -> 0 | Q36: =+P36+O36 -> 0 | R36: 25210 | S36: =+R36*M36 -> 25210 | T36: =+S36*0.19 -> 4789.9 | U36: =+T36+S36 -> 29999.9 | V36: =+U36+Q36 -> 29999.9
H37: 26396 | I37: 43150 | J37: 7639 | K37: PREVENTIVO | L37: DESMANCHADO | M37: 1 | N37: 0 | O37: =+N37*M37 -> 0 | P37: =+O37*0.19 -> 0 | Q37: =+P37+O37 -> 0 | R37: 33613 | S37: =+R37*M37 -> 33613 | T37: =+S37*0.19 -> 6386.47 | U37: =+T37+S37 -> 39999.47 | V37: =+U37+Q37 -> 39999.47
H38: 26249 | I38: 43150 | J38: 7635 | K38: PREVENTIVO | L38: LAVADO EXTERIOR | M38: 1 | N38: 0 | O38: =+N38*M38 -> 0 | P38: =+O38*0.19 -> 0 | Q38: =+P38+O38 -> 0 | R38: 10084 | S38: =+R38*M38 -> 10084 | T38: =+S38*0.19 -> 1915.96 | U38: =+T38+S38 -> 11999.96 | V38: =+U38+Q38 -> 11999.96
H39: 29969 | I39: 43220 | J39: 7668 | K39: PREVENTIVO | L39: LAVADO EXTERIOR | M39: 1 | N39: 0 | O39: =+N39*M39 -> 0 | P39: =+O39*0.19 -> 0 | Q39: =+P39+O39 -> 0 | R39: 10084 | S39: =+R39*M39 -> 10084 | T39: =+S39*0.19 -> 1915.96 | U39: =+T39+S39 -> 11999.96 | V39: =+U39+Q39 -> 11999.96
H40: 26749 | I40: 43220 | J40: 7681 | K40: PREVENTIVO | L40: LAVADO MOTOR | M40: 1 | N40: 0 | O40: =+N40*M40 -> 0 | P40: =+O40*0.19 -> 0 | Q40: =+P40+O40 -> 0 | R40: 15126 | S40: =+R40*M40 -> 15126 | T40: =+S40*0.19 -> 2873.94 | U40: =+T40+S40 -> 17999.94 | V40: =+U40+Q40 -> 17999.94
H41: 31828 | I41: 43220 | J41: 7685 | K41: PREVENTIVO | L41: LAVADO EXTERIOR | M41: 1 | N41: 0 | O41: =+N41*M41 -> 0 | P41: =+O41*0.19 -> 0 | Q41: =+P41+O41 -> 0 | R41: 10084 | S41: =+R41*M41 -> 10084 | T41: =+S41*0.19 -> 1915.96 | U41: =+T41+S41 -> 11999.96 | V41: =+U41+Q41 -> 11999.96
... H46: 33830 | I46: 43266 | J46: 7770 | K46: PREVENTIVO | L46: LAVADO EXTERIOR | M46: 1 | N46: 0 | O46: =+N46*M46 -> 0 | P46: =+O46*0.19 -> 0 | Q46: =+P46+O46 -> 0 | R46: 10084 | S46: =+R46*M46 -> 10084 | T46: =+S46*0.19 -> 1915.96 | U46: =+T46+S46 -> 11999.96 | V46: =+U46+Q46 -> 11999.96
...

Sheet Hoja1
A1: OKZ666 | B1: Repuestos y Mano de obra | C1: Tipo de mantenimiento
A2: TALLERES EL NORTE | B2: ABRAZADERA 450x720 NEGRA | C2: CORRECTIVO
A3: INVERSIONES EL NORTE SAS | B3: ACEITE CHEVRON PARA HIDRAULICO | C3: PREVENTIVO
A4: TALLERES EL NORTE | B4: ACEITE HID ACD PLUS ATF TYPE VI | C4: PREVENTIVO
A5: INVERSIONES EL NORTE SAS | B5: ACEITE HIDRAULICO | C5: PREVENTIVO
A6: INVERSIONES EL NORTE SAS | B6: ACEITE HIDRAULICO CAJA | C6: PREVENTIVO
A7: TALLERES EL NORTE | B7: ACEITE HIDRAULICO DIRECCION | C7: PREVENTIVO
A8: TALLERES EL NORTE | B8: ACEITE MOTOR | C8: PREVENTIVO
A9: TALLERES EL NORTE | B9: ACEITE MOTOR AC DELCO SELE 20W50 | C9: PREVENTIVO
A10: TALLERES EL NORTE | B10: ACEITE SINTETICO | C10: PREVENTIVO
A11: TALLERES EL NORTE | B11: ACEITE SINTETICO 10W40 | C11: PREVENTIVO
A12: INVERSIONES EL NORTE SAS | B12: ACEITE SINTETICO MOTOR | C12: PREVENTIVO
... A385: TALLERES EL NORTE | B385: TORQUEAR SUSPENSION | C385: CORRECTIVO
