Workbook

Sheet OLN047
C1: PERSONERÍA DE BOGOTÁ, D. C. | F1: FORMATO HOJA DE VIDA DE VEHÍCULOS | U1: Codigo: 09-FR-40
U2: Versión: 03 | W2: Pagina: 1
U3: Vigente desde: 24/10/2019
C5: HOJA DE VIDA DEL VEHICULO
C6: INFORMACION GENERAL DEL VEHICULO
C7: PLACA | D7: LÍNEA | E7: TIPO | F7: MARCA | H7: COLOR | J7: NÚMERO DE MOTOR | L7: NÚMERO DE CHASIS | N7: CILINDRAJE | O7: SERIE No. | Q7: TIPO CARROCERÍA | S7: LICENCIA TRÁNSITO No. | U7: No, DE PASAJEROS | V7: TIPO COMBUSTIBLE:
C8: OLN047 | D8: LOGAN | E8: SEDAN | F8: RENAULT | H8: GRIS ESTRELLA | J8: 2842Q147594 | L8: 9FB4SRC94JM167924 | N8: 1599 | O8: 9FB4SRC94JM167924 | Q8: SEDAN | S8: 10015511132 | U8: 5 | V8: GASOLINA
C9: POLIZA SOAT | I9: CERTIFICADO REVISIÓN TECNICO-MECÁNICA Y DE GASES | Q9: INCIDENTES O ACCIDENTES DE TRÁNSITO
C10: Número de poliza | D10: Inicio de vigencia | E10: Fin de vigencia | F10: Número de poliza | G10: Inicio de vigencia | H10: Fin de vigencia | I10: Centro Diagnóstico Autorizado | K10: Inicio de vigencia | L10: Fin de vigencia | M10: Centro Diagnóstico Autorizado | O10: Inicio de vigencia | P10: Fin de vigencia | Q10: Fecha del evento | R10: Nombre del Conductor que reporta | U10: Tipo de evento: Incidente ó Accidente
C11: 184644014 | D11: 43126 | E11: 43490
C12: 14730800001820 | D12: 43856 | E12: 44221
C13: 9201121000593 | D13: 44222 | E13: 44586
C17: DETALLE DE MANTENIMIENTO PREVENTIVO Y CORRECTIVO
C18: Fecha Novedad de Falla Inspección Diaria Vehicular - I.D.V. ó Revisión Preventiva | D18: Kilometraje (en la fecha de la novedad) | E18: Tipo de novedad reportada en I.D.V. ó Revisión Preventiva | F18: Contrato No. | G18: Proveedor | H18: Kilometraje de la autorización de servicios | I18: Fecha factura | J18: Factura No. | K18: Tipo de mantenimiento | L18: Repuestos y Mano de obra | N18: Cant | O18: Valor Unitario Repuesto | P18: Subtotal Repuestos =(P*Q) | Q18: IVA =(R*S) | R18: Valor total repuesto =(R+S) | S18: Valor Unitario Mano de Obra | T18: Subtotal Mano de obra =(P*U) | U18: IVA (V*W) | V18: Valor total Mano de Obra =(V+W) | W18: Total Facturado =(T+X) | X18: TOTAL FACTURA | Y18: DOCUMENTOS SOPORTE
G19: TALLERES EL NORTE | H19: 40023 | I19: 44179 | J19: FT01 235 | K19: =VLOOKUP(L19,Hoja1!B$2:C$401,2,"FALSO") -> PREVENTIVO | L19: ACEITE SINTETICO MOTOR | N19: 4 | O19: 25062 | P19: =+O19*N19 -> 100248 | Q19: =+P19*0.19 -> 19047.12 | R19: =+Q19+P19 -> 119295.12 | S19: 0 | T19: =+S19*N19 -> 0 | U19: =+T19*0.19 -> 0 | V19: =+U19+T19 -> 0 | W19: =+V19+R19 -> 119295.12
G20: TALLERES EL NORTE | H20: 40023 | I20: 44179 | J20: FT01 235 | K20: =VLOOKUP(L20,Hoja1!B$2:C$401,2,"FALSO") -> PREVENTIVO | L20: ACEITE CHEVRON PARA HIDRAULICO | N20: 2 | O20: 21408 | P20: =+O20*N20 -> 42816 | Q20: =+P20*0.19 -> 8135.04 | R20: =+Q20+P20 -> 50951.04 | S20: 0 | T20: =+S20*N20 -> 0 | U20: =+T20*0.19 -> 0 | V20: =+U20+T20 -> 0 | W20: =+V20+R20 -> 50951.04
G21: TALLERES EL NORTE | H21: 40023 | I21: 44179 | J21: FT01 235 | K21: =VLOOKUP(L21,Hoja1!B$2:C$401,2,"FALSO") -> PREVENTIVO | L21: FILTRO ACEITE | N21: 1 | O21: 12562 | P21: =+O21*N21 -> 12562 | Q21: =+P21*0.19 -> 2386.78 | R21: =+Q21+P21 -> 14948.78 | S21: 0 | T21: =+S21*N21 -> 0 | U21: =+T21*0.19 -> 0 | V21: =+U21+T21 -> 0 | W21: =+V21+R21 -> 14948.78
G22: TALLERES EL NORTE | H22: 40023 | I22: 44179 | J22: FT01 235 | K22: =VLOOKUP(L22,Hoja1!B$2:C$401,2,"FALSO") -> PREVENTIVO | L22: FILTRO AIRE | N22: 1 | O22: 30566 | P22: =+O22*N22 -> 30566 | Q22: =+P22*0.19 -> 5807.54 | R22: =+Q22+P22 -> 36373.54 | S22: 0 | T22: =+S22*N22 -> 0 | U22: =+T22*0.19 -> 0 | V22: =+U22+T22 -> 0 | W22: =+V22+R22 -> 36373.54
G23: TALLERES EL NORTE | H23: 40023 | I23: 44179 | J23: FT01 235 | K23: =VLOOKUP(L23,Hoja1!B$2:C$401,2,"FALSO") -> PREVENTIVO | L23: FILTRO AIRE ACONDICIONADO | N23: 1 | O23: 29460 | P23: =+O23*N23 -> 29460 | Q23: =+P23*0.19 -> 5597.4 | R23: =+Q23+P23 -> 35057.4 | S23: 0 | T23: =+S23*N23 -> 0 | U23: =+T23*0.19 -> 0 | V23: =+U23+T23 -> 0 | W23: =+V23+R23 -> 35057.4
G24: TALLERES EL NORTE | H24: 40023 | I24: 44179 | J24: FT01 235 | K24: =VLOOKUP(L24,Hoja1!B$2:C$401,2,"FALSO") -> PREVENTIVO | L24: LIQUIDO DE FRENOS | N24: 2 | O24: 16337 | P24: =+O24*N24 -> 32674 | Q24: =+P24*0.19 -> 6208.06 | R24: =+Q24+P24 -> 38882.06 | S24: 0 | T24: =+S24*N24 -> 0 | U24: =+T24*0.19 -> 0 | V24: =+U24+T24 -> 0 | W24: =+V24+R24 -> 38882.06
G25: TALLERES EL NORTE | H25: 40023 | I25: 44179 | J25: FT01 235 | K25: =VLOOKUP(L25,Hoja1!B$2:C$401,2,"FALSO") -> CORRECTIVO | L25: JUEGO DE BUJIAS | N25: 1 | O25: 46326 | P25: =+O25*N25 -> 46326 | Q25: =+P25*0.19 -> 8801.94 | R25: =+Q25+P25 -> 55127.94 | S25: 0 | T25: =+S25*N25 -> 0 | U25: =+T25*0.19 -> 0 | V25: =+U25+T25 -> 0 | W25: =+V25+R25 -> 55127.94
G26: TALLERES EL NORTE | H26: 40023 | I26: 44179 | J26: FT01 235 | K26: =VLOOKUP(L26,Hoja1!B$2:C$401,2,"FALSO") -> #N/A | L26: LIMPIADOR PARA CUERPO ACELERACION | N26: 1 | O26: 19240 | P26: =+O26*N26 -> 19240 | Q26: =+P26*0.19 -> 3655.6 | R26: =+Q26+P26 -> 22895.6 | S26: 0 | T26: =+S26*N26 -> 0 | U26: =+T26*0.19 -> 0 | V26: =+U26+T26 -> 0 | W26: =+V26+R26 -> 22895.6
G27: TALLERES EL NORTE | H27: 40023 | I27: 44179 | J27: FT01 235 | K27: =VLOOKUP(L27,Hoja1!B$2:C$401,2,"FALSO") -> CORRECTIVO | L27: GAS R 134 | N27: 1 | O27: 140000 | P27: =+O27*N27 -> 140000 | Q27: =+P27*0.19 -> 26600 | R27: =+Q27+P27 -> 166600 | S27: 0 | T27: =+S27*N27 -> 0 | U27: =+T27*0.19 -> 0 | V27: =+U27+T27 -> 0 | W27: =+V27+R27 -> 166600
G28: TALLERES EL NORTE | H28: 40023 | I28: 44179 | J28: FT01 235 | K28: =VLOOKUP(L28,Hoja1!B$2:C$401,2,"FALSO") -> #N/A | L28: REVISION DE FRENOS | N28: 1 | O28: 0 | P28: =+O28*N28 -> 0 | Q28: =+P28*0.19 -> 0 | R28: =+Q28+P28 -> 0 | S28: 24949 | T28: =+S28*N28 -> 24949 | U28: =+T28*0.19 -> 4740.31 | V28: =+U28+T28 -> 29689.31 | W28: =+V28+R28 -> 29689.31
G29: TALLERES EL NORTE | H29: 40023 | I29: 44179 | J29: FT01 235 | K29: =VLOOKUP(L29,Hoja1!B$2:C$401,2,"FALSO") -> PREVENTIVO | L29: CAMBIO DE ACEITE MOTOR, ENTRE OTROS | N29: 1 | O29: 0 | P29: =+O29*N29 -> 0 | Q29: =+P29*0.19 -> 0 | R29: =+Q29+P29 -> 0 | S29: 11824 | T29: =+S29*N29 -> 11824 | U29: =+T29*0.19 -> 2246.56 | V29: =+U29+T29 -> 14070.56 | W29: =+V29+R29 -> 14070.56
G30: TALLERES EL NORTE | H30: 40023 | I30: 44179 | J30: FT01 235 | K30: =VLOOKUP(L30,Hoja1!B$2:C$401,2,"FALSO") -> PREVENTIVO | L30: CAMBIO FILTRO ACEITE, COMBUST, AIRE | N30: 1 | O30: 0 | P30: =+O30*N30 -> 0 | Q30: =+P30*0.19 -> 0 | R30: =+Q30+P30 -> 0 | S30: 9566 | T30: =+S30*N30 -> 9566 | U30: =+T30*0.19 -> 1817.54 | V30: =+U30+T30 -> 11383.54 | W30: =+V30+R30 -> 11383.54
... G37: TALLERES EL NORTE | H37: 40023 | I37: 44179 | J37: FT01 235 | K37: =VLOOKUP(L37,Hoja1!B$2:C$401,2,"FALSO") -> PREVENTIVO | L37: SERVICIO DE SCANER | N37: 1 | O37: 0 | P37: =+O37*N37 -> 0 | Q37: =+P37*0.19 -> 0 | R37: =+Q37+P37 -> 0 | S37: 52182 | T37: =+S37*N37 -> 52182 | U37: =+T37*0.19 -> 9914.58 | V37: =+U37+T37 -> 62096.58 | W37: =+V37+R37 -> 62096.58
G38: TALLERES EL NORTE | H38: 40023 | I38: 44179 | J38: FT01 235 | K38: =VLOOKUP(L38,Hoja1!B$2:C$401,2,"FALSO") -> #N/A | L38: LAVADO Y SINCRONIZADO DE INYECTORES (POR 4) | N38: 1 | O38: 0 | P38: =+O38*N38 -> 0 | Q38: =+P38*0.19 -> 0 | R38: =+Q38+P38 -> 0 | S38: 77504 | T38: =+S38*N38 -> 77504 | U38: =+T38*0.19 -> 14725.76 | V38: =+U38+T38 -> 92229.76 | W38: =+V38+R38 -> 92229.76 | X38: =SUM(W19:W38) -> 1440740.1
G39: TALLERES EL NORTE | H39: 44575 | I39: 44179 | J39: FT01 241 | K39: =VLOOKUP(L39,Hoja1!B$2:C$401,2,"FALSO") -> CORRECTIVO | L39: BOMBILLO HALOGENO H7 12 VOLTIOS | N39: 2 | O39: 27568 | P39: =+O39*N39 -> 55136 | Q39: =+P39*0.19 -> 10475.84 | R39: =+Q39+P39 -> 65611.84 | S39: 0 | T39: =+S39*N39 -> 0 | U39: =+T39*0.19 -> 0 | V39: =+U39+T39 -> 0 | W39: =+V39+R39 -> 65611.84
G40: TALLERES EL NORTE | H40: 44575 | I40: 44179 | J40: FT01 241 | K40: =VLOOKUP(L40,Hoja1!B$2:C$401,2,"FALSO") -> CORRECTIVO | L40: BOMBILLO H16 | N40: 2 | O40: 50700 | P40: =+O40*N40 -> 101400 | Q40: =+P40*0.19 -> 19266 | R40: =+Q40+P40 -> 120666 | S40: 0 | T40: =+S40*N40 -> 0 | U40: =+T40*0.19 -> 0 | V40: =+U40+T40 -> 0 | W40: =+V40+R40 -> 120666
G41: TALLERES EL NORTE | H41: 44575 | I41: 44179 | J41: FT01 241 | K41: =VLOOKUP(L41,Hoja1!B$2:C$401,2,"FALSO") -> #N/A | L41: SERVICIO SCANNER | N41: 1 | O41: 0 | P41: =+O41*N41 -> 0 | Q41: =+P41*0.19 -> 0 | R41: =+Q41+P41 -> 0 | S41: 48710 | T41: =+S41*N41 -> 48710 | U41: =+T41*0.19 -> 9254.9 | V41: =+U41+T41 -> 57964.9 | W41: =+V41+R41 -> 57964.9
G42: TALLERES EL NORTE | H42: 44575 | I42: 44179 | J42: FT01 241 | K42: =VLOOKUP(L42,Hoja1!B$2:C$401,2,"FALSO") -> #N/A | L42: PARCHE RADIAL,DESPINCHE | N42: 1 | O42: 0 | P42: =+O42*N42 -> 0 | Q42: =+P42*0.19 -> 0 | R42: =+Q42+P42 -> 0 | S42: 17941 | T42: =+S42*N42 -> 17941 | U42: =+T42*0.19 -> 3408.79 | V42: =+U42+T42 -> 21349.79 | W42: =+V42+R42 -> 21349.79
G43: TALLERES EL NORTE | H43: 44575 | I43: 44179 | J43: FT01 241 | K43: =VLOOKUP(L43,Hoja1!B$2:C$401,2,"FALSO") -> PREVENTIVO | L43: REVISION DE LUCES | N43: 1 | O43: 0 | P43: =+O43*N43 -> 0 | Q43: =+P43*0.19 -> 0 | R43: =+Q43+P43 -> 0 | S43: 90000 | T43: =+S43*N43 -> 90000 | U43: =+T43*0.19 -> 17100 | V43: =+U43+T43 -> 107100 | W43: =+V43+R43 -> 107100
G44: TALLERES EL NORTE | H44: 44575 | I44: 44179 | J44: FT01 241 | K44: BUSCARV(L44;Hoja1!B$2:C$401;2;"FALSO") | L44: REVISION ELECTRICA | N44: 1 | O44: 0 | P44: =+O44*N44 -> 0 | Q44: =+P44*0.19 -> 0 | R44: =+Q44+P44 -> 0 | S44: 120000 | T44: =+S44*N44 -> 120000 | U44: =+T44*0.19 -> 22800 | V44: =+U44+T44 -> 142800 | W44: =+V44+R44 -> 142800 | X44: =SUM(W39:W44) -> 515492.53
G45: INVERSIONES EL NORTE SAS | H45: 34000 | I45: 44095 | J45: FT 7331 | K45: =VLOOKUP(L45,Hoja1!B$2:C$401,2,"FALSO") -> PREVENTIVO | L45: LLANTA NUEVA POR UNIDAD | N45: 1 | O45: 108066 | P45: =+O45*N45 -> 108066 | Q45: =+P45*0.19 -> 20532.54 | R45: =+Q45+P45 -> 128598.54 | S45: 0 | T45: =+S45*N45 -> 0 | U45: =+T45*0.19 -> 0 | V45: =+U45+T45 -> 0 | W45: =+V45+R45 -> 128598.54
G46: INVERSIONES EL NORTE SAS | H46: 34000 | I46: 44095 | J46: FT 7331 | K46: =VLOOKUP(L46,Hoja1!B$2:C$401,2,"FALSO") -> PREVENTIVO | L46: MONTAJE DE LLANTAS | N46: 1 | O46: 0 | P46: =+O46*N46 -> 0 | Q46: =+P46*0.19 -> 0 | R46: =+Q46+P46 -> 0 | S46: 8282 | T46: =+S46*N46 -> 8282 | U46: =+T46*0.19 -> 1573.58 | V46: =+U46+T46 -> 9855.58 | W46: =+V46+R46 -> 9855.58 | X46: =SUM(W45:W46) -> 138454.12
G47: TALLERES EL NORTE | H47: NO | I47: 44237 | J47: FC01 24 | K47: =VLOOKUP(L47,Hoja1!B$2:C$401,2,"FALSO") -> CORRECTIVO | L47: DIRECCIONAL ESPEJO | N47: 1 | O47: 154000 | P47: =+O47*N47 -> 154000 | Q47: =+P47*0.19 -> 29260 | R47: =+Q47+P47 -> 183260 | S47: 0 | T47: =+S47*N47 -> 0 | U47: =+T47*0.19 -> 0 | V47: =+U47+T47 -> 0 | W47: =+V47+R47 -> 183260
G48: TALLERES EL NORTE | H48: 41000 | I48: 44308 | J48: FC01 164 | K48: =VLOOKUP(L48,Hoja1!B$2:C$401,2,"FALSO") -> CORRECTIVO | L48: BATERIA | N48: 1 | O48: 228910 | P48: =+O48*N48 -> 228910 | Q48: =+P48*0.19 -> 43492.9 | R48: =+Q48+P48 -> 272402.9 | S48: 0 | T48: =+S48*N48 -> 0 | U48: =+T48*0.19 -> 0 | V48: =+U48+T48 -> 0 | W48: =+V48+R48 -> 272402.9
G49: TALLERES EL NORTE | H49: 41000 | I49: 44308 | J49: FC01 164 | K49: =VLOOKUP(L49,Hoja1!B$2:C$401,2,"FALSO") -> PREVENTIVO | L49: KIT FELPA PARA BATERIA | N49: 1 | O49: 3500 | P49: =+O49*N49 -> 3500 | Q49: =+P49*0.19 -> 665 | R49: =+Q49+P49 -> 4165 | S49: 0 | T49: =+S49*N49 -> 0 | U49: =+T49*0.19 -> 0 | V49: =+U49+T49 -> 0 | W49: =+V49+R49 -> 4165
G50: TALLERES EL NORTE | H50: 41000 | I50: 44308 | J50: FC01 164 | K50: =VLOOKUP(L50,Hoja1!B$2:C$401,2,"FALSO") -> PREVENTIVO | L50: FUSIBLE | N50: 2 | O50: 5000 | P50: =+O50*N50 -> 10000 | Q50: =+P50*0.19 -> 1900 | R50: =+Q50+P50 -> 11900 | S50: 0 | T50: =+S50*N50 -> 0 | U50: =+T50*0.19 -> 0 | V50: =+U50+T50 -> 0 | W50: =+V50+R50 -> 11900
...

Sheet Hoja1
A1: OLN047 | B1: Repuestos y Mano de obra | C1: Tipo de mantenimiento
A2: TALLERES EL NORTE | B2: ABRAZADERA 450x720 NEGRA | C2: CORRECTIVO
A3: INVERSIONES EL NORTE SAS | B3: ACEITE CHEVRON PARA HIDRAULICO | C3: PREVENTIVO
A4: TALLERES EL NORTE | B4: ACEITE HID ACD PLUS ATF TYPE VI | C4: PREVENTIVO
A5: INVERSIONES EL NORTE SAS | B5: ACEITE HIDRAULICO | C5: PREVENTIVO
A6: INVERSIONES EL NORTE SAS | B6: ACEITE HIDRAULICO CAJA | C6: PREVENTIVO
A7: TALLERES EL NORTE | B7: ACEITE HIDRAULICO DIRECCION | C7: PREVENTIVO
A8: TALLERES EL NORTE | B8: ACEITE MOTOR | C8: PREVENTIVO
A9: TALLERES EL NORTE | B9: ACEITE MOTOR AC DELCO SELE 20W50 | C9: PREVENTIVO
A10: TALLERES EL NORTE | B10: ACEITE SINTETICO | C10: PREVENTIVO
A11: TALLERES EL NORTE | B11: ACEITE SINTETICO 10W40 | C11: PREVENTIVO
A12: INVERSIONES EL NORTE SAS | B12: ACEITE SINTETICO MOTOR | C12: PREVENTIVO
... A431: TALLERES EL NORTE | B431: RECARGA AIRE ACONDICIONADO | C431: CORRECTIVO
